Workbook

Sheet HOME PAGE
A1: INVESTMENTS AND LOANS (FINANCIAL CALCULATOR)

Sheet Assignment1(Back End)
A1: Given Interest Rate | B1: ='Assignment1(User Interface)'!B3 -> 0 | D1: Requested
A2: Compunding Period Given | B2: ='Assignment1(User Interface)'!B4 -> 0 | D2: Compounding periods | E2: ='Assignment1(User Interface)'!G3 -> 0
A3: Years | B3: ='Assignment1(User Interface)'!B5 -> 0 | D3: Years | E3: ='Assignment1(User Interface)'!B5 -> 0
E6: From
E7: Simple | F7: Effective Annual rate | G7: Nominal | H7: Effective Periodic | I7: Continuous
C8: To | D8: Simple | E8: =(B1*B2*B3)/(E2*B3) -> #DIV/0! | F8: =((((1+B1)^B3))-1)/(E2) -> #DIV/0! | G8: =(((1+$B$1/$B$2))^($B$3*$B$2)-1)/$E$2*$B$3 -> #DIV/0! | H8: =(((1+B1))^(B3*B2)-1)/E2*B3 -> #DIV/0! | I8: =(EXP(B1*B3)-1)/(B3*B2) -> #DIV/0!
D9: Effective Annual rate | E9: =((1+B1*B3*B2)^(1/E2))-1 -> #DIV/0! | F9: =((1+B1)^(B3/E3))-1 -> #DIV/0! | G9: =((((1+(B1/B2))^(B2*B3)))^(1/E2))-1 -> #DIV/0! | H9: =(((1+(B1))^((B2*B3)/E3)))-1 -> #DIV/0! | I9: =(EXP(B1)-1) -> 0
D10: Nominal | E10: =((1+(B1*B3*B2))^(1/(E3*E2))-1)*E2 -> #DIV/0! | F10: =((((1+B1)^B3)^(1/E2*E3))-1)*E2 -> #DIV/0! | G10: =((((1+(B1/B2))^((B2*B3)/(E2*E3))))-1)*E2 -> #DIV/0! | H10: =(((1+(B1))^((B2*B3)/(E2*E3))-1))*E2 -> #DIV/0! | I10: =((EXP(B1/E2))-1)*E2 -> #DIV/0!
D11: Effective Periodic | E11: =((1+(B1*B3*B2))^(1/(E3*E2))-1) -> #DIV/0! | F11: =(((1+B1)^(B3))^(1/(E2*E3)))-1 -> #DIV/0! | G11: =((((1+(B1/B2))^((B2*B3)/(E2*E3))))-1) -> #DIV/0! | H11: =(((1+(B1))^(B2*B3))^(1/(E2*E3)))-1 -> #DIV/0! | I11: =((EXP(B1/E2))-1) -> #DIV/0!
D12: Continuous | E12: =(LN(1+B1*B3*B2))/E3 -> #DIV/0! | F12: =(LN((1+B1)^B3)) -> 0 | G12: =(LN((1+(B1/B2))^(B2*B3)))/E3 -> #DIV/0! | H12: =((LN((1+(B1/B2)^B3))))/E3 -> #DIV/0! | I12: =LN(EXP(B3*B1)) -> 0

Sheet Assignment1(User Interface)
A1: Givens | F1: Requested
A2: Given Type | B2: Continuous | F2: Requested Int Rate Type | G2: Effective periodic
A3: Given Interest Rate | F3: Requested compounding periods | N3: Simple
A4: Given Compound period | F4: The requested rate is: | G4: =IF(AND(B2=N3,G2=N3),'Assignment1(Back End)'!E8,IF(AND(B2=N3,G2=N4),'Assignment1(Back End)'!E9,IF(AND(B2=N3,G2=N5),'Assignment1(Back End)'!E10,IF(AND(B2=N3,G2=N6),'Assignment1(Back End)'!E11,IF(AND(B2=N3,G2=N7),'Assignment1(Back End)'!E12,IF(AND(B2=N4,G2=N3),'Assignment1(Back End)'!F8,IF(AND(B2=N4,G2=N4),'Assignment1(Back End)'!F9,IF(AND(B2=N4,G2=N5),'Assignment1(Back End)'!F10,IF(AND(B2=N4,G2=N6),'Assignment1(Back End)'!F11,IF(AND(B2=N4,G2=N7),'Assignment1(Back End)'!F12,IF(AND(B2=N5,G2=N3),'Assignment1(Back End)'!G8,IF(AND(B2=N5,G2=N4),'Assignment1(Back End)'!G9,IF(AND(B2=N5,G2=N5),'Assignment1(Back End)'!G10,IF(AND(B2=N5,G2=N6),'Assignment1(Back End)'!G11,IF(AND(B2=N5,G2=N7),'Assignment1(Back End)'!G12,IF(AND(B2=N6,G2=N3),'Assignment1(Back End)'!H8,IF(AND(B2=N6,G2=N4),'Assignment1(Back End)'!H9,IF(AND(B2=N6,G2=N5),'Assignment1(Back End)'!H10,IF(AND(B2=N6,G2=N6),'Assignment1(Back End)'!H11,IF(AND(B2=N6,G2=N7),'Assignment1(Back End)'!H12,IF(AND(B2=N7,G2=N3),'Assignment1(Back End)'!I8,IF(AND(B2=N7,G2=N4),'Assignment1(Back End)'!I9,IF(AND(B2=N7,G2=N5),'Assignment1(Back End)'!I10,IF(AND(B2=N7,G2=N6),'Assignment1(Back End)'!I11,IF(AND(B2=N7,G2=N7),'Assignment1(Back End)'!I12,"Still work to do"))))))))))))))))))))))))) -> #DIV/0! | N4: Effective annual
A5: Number of years | N5: Nominal
N6: Effective periodic
N7: Continuous

Sheet Assignment2 (Back End)
A1: Given
A2: Future value | B2: ='Assignment2(User Interface)'!B7 -> 0
A3: Present Value | B3: ='Assignment2(User Interface)'!B8 -> 0
A4: Number of years | B4: =IF('Assignment2(User Interface)'!B9='Assignment2(User Interface)'!W2,'Assignment2(User Interface)'!D12,IF('Assignment2(User Interface)'!B9='Assignment2(User Interface)'!W3,'Assignment2(User Interface)'!B12)) -> 8
A5: Interest | B5: ='Assignment2(User Interface)'!B10 -> 0
A6: Period | B6: ='Assignment2(User Interface)'!B11 -> 0
A7: years
B8: Find
A9: Rates | C9: Future Value | D9: Present Value | E9: Number of Years | F9: Interest | G9: Period | H9: Interest Earned
B10: Simple | C10: =((B3)*(1+(B5*B4*B6))) -> 0 | D10: =B2/(1+(B5*B6*B4)) -> 0 | E10: =((B2/B3)-1)/(B5*B6) -> #DIV/0! | F10: =((B2/B3)-1)/(B4*B6) -> #DIV/0! | G10: =((B2/B3)-1)/(B5*B4) -> #DIV/0! | H10: =C10-D10 -> 0
B11: Effective Annual | C11: =B3*(1+B5)^B4 -> 0 | D11: =B2/((1+B5)^B4) -> 0 | E11: =LOG((B2/B3), (1+B5)) -> #DIV/0! | F11: =((B2/B3)^(1/B4))-1 -> #DIV/0! | G11: 1 | H11: =C11-D11 -> 0
B12: Effective periodic | C12: =B3*(1+B5)^(B6*B4) -> 0 | D12: =B2/((1+B5)^(B4*B6)) -> 0 | E12: =LOG((B2/B3),(1+B5))/B4 -> #DIV/0! | F12: =((B2/B3)^(1/(B4*B6)))-1 -> #DIV/0! | G12: =LOG((B2/B3),(1+B5))/B4 -> #DIV/0! | H12: =C12-D12 -> 0
B13: Nominal | C13: =B3*((1+(B5/B6))^(B4*B6)) -> #DIV/0! | D13: =B2/((1+(B5/B6))^(B4*B6)) -> #DIV/0! | E13: =LOG((B2/B3), (1+(B5/B6)))/B6 -> #DIV/0! | F13: =(((B2/B3)^(1/(B4*B6)))-1)*B6 -> #DIV/0! | G13: =LOG((B2/B3), (1+(B5/B6)))/B4 -> #DIV/0! | H13: =C13-D13 -> #DIV/0!
B14: Continuous | C14: =B3*(EXP(B5*B4)) -> 0 | D14: =B3*(EXP(-B5*B4)) -> 0 | E14: =(LN(B2/B3))/B5 -> #DIV/0! | F14: =(LN(B2/B3))/B4 -> #DIV/0! | G14: =(LN(B2/B3))/B5 -> #DIV/0! | H14: =C14-D14 -> 0

Sheet Assignment2(User Interface)
A1: INVESTMENT CALCULATOR
U2: Simple | V2: Future value | W2: Exact years
A3: Interest RateType | B3: Effective periodic | D3: Unknown Variable | E3: Future value | U3: Effective Annual | V3: Present Value | W3: Dates
U4: Effective periodic | V4: Number of years
D5: Variable Value | E5: =IF(AND(B3=U2,E3=V2),'Assignment2 (Back End)'!C10,IF(AND(B3=U2,E3=V3),'Assignment2 (Back End)'!D10,IF(AND(B3=U2,E3=V4),'Assignment2 (Back End)'!E10,IF(AND(B3=U2,E3=V5),TEXT('Assignment2 (Back End)'!$F$10,"0.0000%"),IF(AND(B3=U2,E3=V6),'Assignment2 (Back End)'!G10,IF(AND(B3=U2,E3=V7),'Assignment2 (Back End)'!H10,IF(AND(B3=U3,E3=V2),'Assignment2 (Back End)'!C11,IF(AND(B3=U3,E3=V3),'Assignment2 (Back End)'!D10,IF(AND(B3=U3,E3=V4),'Assignment2 (Back End)'!E11,IF(AND(B3=U3,E3=V5),TEXT('Assignment2 (Back End)'!F11,"0.0000%"),IF(AND(B3=U3,E3=V6),'Assignment2 (Back End)'!G11,IF(AND(B3=U3,E3=V7),'Assignment2 (Back End)'!H11,IF(AND(B3=U4,E3=V2),'Assignment2 (Back End)'!C12,IF(AND(B3=U4,E3=V3),'Assignment2 (Back End)'!D11,IF(AND(B3=U4,E3=V4),'Assignment2 (Back End)'!E12,IF(AND(B3=U4,E3=V5),TEXT('Assignment2 (Back End)'!F12,"0.0000%"),IF(AND(B3=U4,E3=V6),'Assignment2 (Back End)'!G12,IF(AND(B3=U4,E3=V7),'Assignment2 (Back End)'!H12,IF(AND(B3=U5,E3=V2),'Assignment2 (Back End)'!C13,IF(AND(B3=U5,E3=V3),'Assignment2 (Back End)'!D13,IF(AND(B3=U5,E3=V4),'Assignment2 (Back End)'!E13,IF(AND(B3=U5,E3=V5),TEXT('Assignment2 (Back End)'!F13,"0.0000%"),IF(AND(B3=U5,E3=V6),'Assignment2 (Back End)'!G13,IF(AND(B3=U5,E3=V7),'Assignment2 (Back End)'!H13,IF(AND(B3=U6,E3=V2),'Assignment2 (Back End)'!C14,IF(AND(B3=U6,E3=V3),'Assignment2 (Back End)'!D14,IF(AND(B3=U6,E3=V5),TEXT('Assignment2 (Back End)'!F14,"0.0000%"),IF(AND(B3=U6,E3=V4),'Assignment2 (Back End)'!E14,IF(AND(B3=U6,E3=V6),'Assignment2 (Back End)'!G14,IF(AND(B3=U6,E3=V7),'Assignment2 (Back End)'!H14,"Not Applicable")))))))))))))))))))))))))))))) -> 0 | G5: Increasing Annuities | U5: Nominal | V5: Interest
A6: Given Variables: | U6: Continuous | V6: Period
A7: Future value | D7: Real Future value | E7: =IF(E3=V2,E5*(1+5%)^(-'Assignment2 (Back End)'!B4)," ") -> 0 | G7: Interest converter | V7: Interest Earned
A8: Present Value
A9: Final Number of years | B9: Exact years | G9: HOME
A10: Interest
A11: Period
A12: Number of years in date: | C12: Manualy Entered years: | D12: 8
A13: Start Date (yyyy/mm/dd):
A14: End Date (yyyy/mm/dd):
A15: INTEREST COMPARISON TABLES
A17: Interest Rate Option 1: | B17: Simple | D17: Interest Rate Option 2: | E17: Effective periodic
A19: Periods(Years) | B19: =B17 -> Simple | D19: Periods(Years) | E19: =E17 -> Effective periodic
A20: 1 | B20: =IF($B$17=$U$2,$B$8*(1+($B$10*1*$B$11)),IF($B$17=$U$3,$B$8*((1+$B$10)^1),IF($B$17=$U$4,$B$8*((1+$B$10)^(1*$B$11)),IF($B$17=$U$5,$B$8*((1+($B$10/$B$11))^(1*$B$11)),IF($B$17=$U$6,$B$8*EXP($B$10*1),"Not Applicable"))))) -> 0 | D20: 1 | E20: =IF($E$17=$U$2,$B$8*(1+($B$10*1*$B$11)),IF($E$17=$U$3,$B$8*((1+$B$10)^1),IF($E$17=$U$4,$B$8*((1+$B$10)^(1*$B$11)),IF($E$17=$U$5,$B$8*((1+($B$10/$B$11))^(1*$B$11)),"Not Applicable")))) -> 0
A21: 2 | B21: =IF($B$17=$U$2,$B$8*(1+($B$10*2*$B$11)),IF($B$17=$U$3,$B$8*((1+$B$10)^2),IF($B$17=$U$4,$B$8*((1+$B$10)^(2*$B$11)),IF($B$17=$U$5,$B$8*((1+($B$10/$B$11))^(2*$B$11)),IF($B$17=$U$6,$B$8*EXP($B$10*2),"Not Applicable"))))) -> 0 | D21: 2 | E21: =IF($E$17=$U$2,$B$8*(1+($B$10*2*$B$11)),IF($E$17=$U$3,$B$8*((1+$B$10)^2),IF($E$17=$U$4,$B$8*((1+$B$10)^(2*$B$11)),IF($E$17=$U$5,$B$8*((1+($B$10/$B$11))^(2*$B$11)),"Not Applicable")))) -> 0
A22: 3 | B22: =IF($B$17=$U$2,$B$8*(1+($B$10*3*$B$11)),IF($B$17=$U$3,$B$8*((1+$B$10)^3),IF($B$17=$U$4,$B$8*((1+$B$10)^(3*$B$11)),IF($B$17=$U$5,$B$8*((1+($B$10/$B$11))^(3*$B$11)),IF($B$17=$U$6,$B$8*EXP($B$10*3),"Not Applicable"))))) -> 0 | D22: 3 | E22: =IF($E$17=$U$2,$B$8*(1+($B$10*3*$B$11)),IF($E$17=$U$3,$B$8*((1+$B$10)^3),IF($E$17=$U$4,$B$8*((1+$B$10)^(3*$B$11)),IF($E$17=$U$5,$B$8*((1+($B$10/$B$11))^(3*$B$11)),"Not Applicable")))) -> 0
A23: 4 | B23: =IF($B$17=$U$2,$B$8*(1+($B$10*4*$B$11)),IF($B$17=$U$3,$B$8*((1+$B$10)^4),IF($B$17=$U$4,$B$8*((1+$B$10)^(4*$B$11)),IF($B$17=$U$5,$B$8*((1+($B$10/$B$11))^(4*$B$11)),IF($B$17=$U$6,$B$8*EXP($B$10*4),"Not Applicable"))))) -> 0 | D23: 4 | E23: =IF($E$17=$U$2,$B$8*(1+($B$10*4*$B$11)),IF($E$17=$U$3,$B$8*((1+$B$10)^4),IF($E$17=$U$4,$B$8*((1+$B$10)^(4*$B$11)),IF($E$17=$U$5,$B$8*((1+($B$10/$B$11))^(4*$B$11)),"Not Applicable")))) -> 0
A24: 5 | B24: =IF($B$17=$U$2,$B$8*(1+($B$10*5*$B$11)),IF($B$17=$U$3,$B$8*((1+$B$10)^5),IF($B$17=$U$4,$B$8*((1+$B$10)^(5*$B$11)),IF($B$17=$U$5,$B$8*((1+($B$10/$B$11))^(5*$B$11)),IF($B$17=$U$6,$B$8*EXP($B$10*5),"Not Applicable"))))) -> 0 | D24: 5 | E24: =IF($E$17=$U$2,$B$8*(1+($B$10*5*$B$11)),IF($E$17=$U$3,$B$8*((1+$B$10)^5),IF($E$17=$U$4,$B$8*((1+$B$10)^(5*$B$11)),IF($E$17=$U$5,$B$8*((1+($B$10/$B$11))^(5*$B$11)),"Not Applicable")))) -> 0
A25: 6 | B25: =IF($B$17=$U$2,$B$8*(1+($B$10*6*$B$11)),IF($B$17=$U$3,$B$8*((1+$B$10)^6),IF($B$17=$U$4,$B$8*((1+$B$10)^(6*$B$11)),IF($B$17=$U$5,$B$8*((1+($B$10/$B$11))^(6*$B$11)),IF($B$17=$U$6,$B$8*EXP($B$10*6),"Not Applicable"))))) -> 0 | D25: 6 | E25: =IF($E$17=$U$2,$B$8*(1+($B$10*6*$B$11)),IF($E$17=$U$3,$B$8*((1+$B$10)^6),IF($E$17=$U$4,$B$8*((1+$B$10)^(6*$B$11)),IF($E$17=$U$5,$B$8*((1+($B$10/$B$11))^(6*$B$11)),"Not Applicable")))) -> 0
A26: 7 | B26: =IF($B$17=$U$2,$B$8*(1+($B$10*7*$B$11)),IF($B$17=$U$3,$B$8*((1+$B$10)^7),IF($B$17=$U$4,$B$8*((1+$B$10)^(7*$B$11)),IF($B$17=$U$5,$B$8*((1+($B$10/$B$11))^(7*$B$11)),IF($B$17=$U$6,$B$8*EXP($B$10*7),"Not Applicable"))))) -> 0 | D26: 7 | E26: =IF($E$17=$U$2,$B$8*(1+($B$10*7*$B$11)),IF($E$17=$U$3,$B$8*((1+$B$10)^7),IF($E$17=$U$4,$B$8*((1+$B$10)^(7*$B$11)),IF($E$17=$U$5,$B$8*((1+($B$10/$B$11))^(7*$B$11)),"Not Applicable")))) -> 0
A27: 8 | B27: =IF($B$17=$U$2,$B$8*(1+($B$10*8*$B$11)),IF($B$17=$U$3,$B$8*((1+$B$10)^8),IF($B$17=$U$4,$B$8*((1+$B$10)^(8*$B$11)),IF($B$17=$U$5,$B$8*((1+($B$10/$B$11))^(8*$B$11)),IF($B$17=$U$6,$B$8*EXP($B$10*8),"Not Applicable"))))) -> 0 | D27: 8 | E27: =IF($E$17=$U$2,$B$8*(1+($B$10*8*$B$11)),IF($E$17=$U$3,$B$8*((1+$B$10)^8),IF($E$17=$U$4,$B$8*((1+$B$10)^(8*$B$11)),IF($E$17=$U$5,$B$8*((1+($B$10/$B$11))^(8*$B$11)),"Not Applicable")))) -> 0

Sheet Assignment3 (Back End)
A1: Given
A2: Future Value | B2: ='Assignment3 (User Interface)'!B8 -> 6600
A3: Present Value | B3: ='Assignment3 (User Interface)'!B9 -> 600
A4: Annuity | B4: ='Assignment3 (User Interface)'!B10 -> 600
A5: Period | B5: ='Assignment3 (User Interface)'!B11 -> 2.5
A6: Years | B6: ='Assignment3 (User Interface)'!B13 -> 18.737851
A7: Interest | B7: ='Assignment3 (User Interface)'!B17 -> 0.05
D9: Givens
D10: Future Value in Arrears | E10: Present Value in Arrears | F10: Future Value in Advance | G10: Present Value in advance | H10: Given Future value and Present value | I10: Continuous Future | J10: Continuous Present
B11: Uknowns | C11: Future Value | D11: =($B$4)*(((1+$B$7)^($B$6*$B$5))-1)/$B$7 -> 105973.93 | E11: =($B$4)*(((1+$B$7)^($B$6*$B$5))-1)/$B$7 -> 105973.93 | F11: =($B$4*(1+$B$7)*(((1+$B$7)^($B$6*$B$5))-1))/$B$7 -> 111272.63 | G11: =($B$4*(1+$B$7)*(((1+$B$7)^($B$6*$B$5))-1))/$B$7 -> 111272.63 | H11: =$B$3*((1+$B$7)^($B$6*$B$5)) -> 5898.6966 | I11: =(B4*(EXP(B7*B6)-1))/B7 -> 18624.465
C12: Present Vaue | D12: =$B$4*(((1-(1+$B$7)^(-$B$5*$B$6)))/$B$7) -> 10779.391 | E12: =$B$4*(((1-(1+$B$7)^(-$B$5*$B$6)))/$B$7) -> 10779.391 | F12: =($B$4*(1+$B$7)*(1-((1+$B$7)^(-$B$6*$B$5))))/$B$7 -> 11318.361 | G12: =($B$4*(1+$B$7)*(1-((1+$B$7)^(-$B$6*$B$5))))/$B$7 -> 11318.361 | H12: =B2/((1+$B$7)^($B$6*$B$5)) -> 671.33475 | I12: =B4*(1-EXP(-B7*B6))/B7 -> 7297.877 | J12: =B3 -> 600
C13: Anuuity | D13: =B2/(((1+B7)^(B6*B5)-1)/B7) -> 37.36768 | E13: =B3/((1-(1+B7)^(-B6*B5))/B7) -> 33.397062 | F13: =$B$2/((((1+$B$7)*(((1+$B$7)^($B$6*$B$5))-1))/$B$7)) -> 35.588267 | G13: =$B$3/(((1+$B$7)*(1-((1+$B$7)^(-$B$5*$B$6))))/$B$7) -> 31.806726 | H13: =B3/((1-(1+B7)^(-B6*B5))/B7) -> 33.397062 | I13: =B2/((EXP(B7*B6)-1)/B7) -> 212.62356 | J13: =B3/((1-(EXP(-B7*B6)))/B7) -> 49.329415
C14: Years | D14: =LOG(((B7*B2)/B4)+1, 1+B7)/B5 -> 3.5929777 | E14: =-LOG10(1-(B3*B7)/B4)/(B5*LOG10(1+B7)) -> 0.4205216 | F14: =(LOG((($B$2*$B$7)/($B$4*(1+$B$7)))+1, 1+$B$7))/B5 -> 3.4532654 | G14: =(LOG((1-(($B$3*$B$7)/($B$4*(1+$B$7)))), 1+$B$7))/-$B$5 -> 0.4 | H14: =(LOG(($B$2/$B$3), 1+$B$7))/$B$5 -> 19.658842 | I14: =(1/B7)*(LN(((B2*B7)/B4)+1)) -> 8.7650986 | J14: =(-1/B7)*((LN(1-((B3*B7)/B4)))) -> 1.0258659
C15: Periods | D15: =LOG(((B7*B2)/B4)+1, 1+B7)/B6 -> 0.47937431 | E15: =LOG((1-((B3*B7)/B4)), (1+B7))/-B6 -> 0.056105901 | F15: =(LOG((($B$2*$B$7)/($B$4*(1+$B$7)))+1, 1+$B$7))/B6 -> 0.46073392 | G15: =(LOG((1-(($B$3*$B$7)/($B$4*(1+$B$7)))), 1+$B$7))/-$B$6 -> 0.053367914 | H15: =(LOG(($B$2/$B$3), 1+$B$7))/$B$6 -> 2.6228784 | I15: =(1/B7)*(LN(((B2*B7)/B4)+1)) -> 8.7650986 | J15: =(-1/B7)*((LN(1-((B3*B7)/B4)))) -> 1.0258659
C16: Interest | D16: =D21 -> 0.05 | E16: =H21 -> 0.05 | F16: =L21 -> 0.05 | G16: =P21 -> 0.05 | H16: =T21 -> 0.05 | I16: =X21 -> 0.05 | J16: =AB21 -> 0.05
A19: Future Value in Arrears | E19: Present Value in Arrears | I19: Future Value in Advance | M19: Present Value in advance | Q19: Given Future value and Present value | U19: Continuous Future Value | Y19: Continuous Present Value
A20: Difference | C20: Future Value | D20: Interest: | E20: Difference | G20: Present Value | H20: Interest: | I20: Difference | K20: Future Value | L20: Interest: | M20: Difference | O20: Present Value | P20: Interest: | Q20: Difference | S20: FV | T20: Interest: | U20: Difference | W20: FV | X20: Interest: | Y20: Difference | AA20: PV | AB20: Interest:
A21: =ABS($D$11-C21) -> 77213.147 | B21: 0.001 | C21: =($B$4)*(((1+B21)^($B$6*$B$5))-1)/B21 -> 28760.786 | D21: =VLOOKUP(D23, A21:B1020,2,FALSE) -> 0.05 | E21: =ABS($E$12-G21) -> 16665.818 | F21: 0.001 | G21: =$B$4*(((1-(1+F21)^(-$B$5*$B$6)))/F21) -> 27445.209 | H21: =VLOOKUP(H23,E21:F1020, 2, FALSE) -> 0.05 | I21: =ABS($F$11-K21) -> 82483.083 | J21: 0.001 | K21: =($B$4*(1+J21)*(((1+J21)^($B$6*$B$5))-1))/J21 -> 28789.546 | L21: =VLOOKUP(L23, I21:J1020, 2, FALSE) -> 0.05 | M21: =ABS($G$12-O21) -> 16154.294 | N21: 0.001 | O21: =($B$4*(1+N21)*(1-((1+N21)^(-$B$6*$B$5))))/N21 -> 27472.655 | P21: =VLOOKUP(P23, M21:N1020, 2, FALSE) -> 0.05 | Q21: =ABS($H$11-S21) -> 5269.9358 | R21: 0.001 | S21: =$B$3*((1+R21)^($B$6*$B$5)) -> 628.76079 | T21: =VLOOKUP(T23, Q21:R1020, 2, FALSE) -> 0.05 | U21: =ABS($I$11-W21) -> 7275.7611 | V21: 0.001 | W21: =($B$4*(EXP(V21*$B$6)-1))/V21 -> 11348.704 | X21: =VLOOKUP(X23, U21:V1020, 2, FALSE) -> 0.05 | Y21: =ABS($I$12-AA21) -> 3840.1562 | Z21: 0.001 | AA21: =$B$4*(1-EXP(-Z21*$B$6))/Z21 -> 11138.033 | AB21: =VLOOKUP(AB23, Y21:Z1020, 2, FALSE) -> 0.05
A22: =ABS($D$11-C22) -> 76539.23 | B22: 0.002 | C22: =($B$4)*(((1+B22)^($B$6*$B$5))-1)/B22 -> 29434.703 | D22: Minimum: | E22: =ABS($E$12-G22) -> 16025.347 | F22: 0.002 | G22: =$B$4*(((1-(1+F22)^(-$B$5*$B$6)))/F22) -> 26804.738 | H22: Minimum: | I22: =ABS($F$11-K22) -> 81779.057 | J22: 0.002 | K22: =($B$4*(1+J22)*(((1+J22)^($B$6*$B$5))-1))/J22 -> 29493.572 | L22: Minimum: | M22: =ABS($G$12-O22) -> 15539.986 | N22: 0.002 | O22: =($B$4*(1+N22)*(1-((1+N22)^(-$B$6*$B$5))))/N22 -> 26858.347 | P22: Minimum: | Q22: =ABS($H$11-S22) -> 5239.8272 | R22: 0.002 | S22: =$B$3*((1+R22)^($B$6*$B$5)) -> 658.86941 | T22: Minimum: | U22: =ABS($I$11-W22) -> 7168.4335 | V22: 0.002 | W22: =($B$4*(EXP(V22*$B$6)-1))/V22 -> 11456.031 | X22: Minimum: | Y22: =ABS($I$12-AA22) -> 3736.7764 | Z22: 0.002 | AA22: =$B$4*(1-EXP(-Z22*$B$6))/Z22 -> 11034.653 | AB22: Minimum:
A23: =ABS($D$11-C23) -> 75844.738 | B23: 0.003 | C23: =($B$4)*(((1+B23)^($B$6*$B$5))-1)/B23 -> 30129.195 | D23: =MIN(A21:A1020) -> 0 | E23: =ABS($E$12-G23) -> 15405.2 | F23: 0.003 | G23: =$B$4*(((1-(1+F23)^(-$B$5*$B$6)))/F23) -> 26184.591 | H23: =MIN(E21:E1020) -> 0 | I23: =ABS($F$11-K23) -> 81053.047 | J23: 0.003 | K23: =($B$4*(1+J23)*(((1+J23)^($B$6*$B$5))-1))/J23 -> 30219.582 | L23: =MIN(I21:I1020) -> 0 | M23: =ABS($G$12-O23) -> 14944.784 | N23: 0.003 | O23: =($B$4*(1+N23)*(1-((1+N23)^(-$B$6*$B$5))))/N23 -> 26263.145 | P23: =MIN(M21:M1020) -> 0 | Q23: =ABS($H$11-S23) -> 5208.309 | R23: 0.003 | S23: =$B$3*((1+R23)^($B$6*$B$5)) -> 690.38758 | T23: =MIN(Q21:Q1020) -> 0 | U23: =ABS($I$11-W23) -> 7059.7526 | V23: 0.003 | W23: =($B$4*(EXP(V23*$B$6)-1))/V23 -> 11564.712 | X23: =MIN(U21:U1020) -> 0 | Y23: =ABS($I$12-AA23) -> 3634.6759 | Z23: 0.003 | AA23: =$B$4*(1-EXP(-Z23*$B$6))/Z23 -> 10932.553 | AB23: =MIN(Y21:Y1020) -> 0
A24: =ABS($D$11-C24) -> 75128.981 | B24: 0.004 | C24: =($B$4)*(((1+B24)^($B$6*$B$5))-1)/B24 -> 30844.951 | E24: =ABS($E$12-G24) -> 14804.639 | F24: 0.004 | G24: =$B$4*(((1-(1+F24)^(-$B$5*$B$6)))/F24) -> 25584.03 | I24: =ABS($F$11-K24) -> 80304.298 | J24: 0.004 | K24: =($B$4*(1+J24)*(((1+J24)^($B$6*$B$5))-1))/J24 -> 30968.331 | M24: =ABS($G$12-O24) -> 14368.005 | N24: 0.004 | O24: =($B$4*(1+N24)*(1-((1+N24)^(-$B$6*$B$5))))/N24 -> 25686.366 | Q24: =ABS($H$11-S24) -> 5175.3168 | R24: 0.004 | S24: =$B$3*((1+R24)^($B$6*$B$5)) -> 723.37981 | U24: =ABS($I$11-W24) -> 6949.6991 | V24: 0.004 | W24: =($B$4*(EXP(V24*$B$6)-1))/V24 -> 11674.766 | Y24: =ABS($I$12-AA24) -> 3533.8371 | Z24: 0.004 | AA24: =$B$4*(1-EXP(-Z24*$B$6))/Z24 -> 10831.714
A25: =ABS($D$11-C25) -> 74391.246 | B25: 0.005 | C25: =($B$4)*(((1+B25)^($B$6*$B$5))-1)/B25 -> 31582.687 | E25: =ABS($E$12-G25) -> 14222.952 | F25: 0.005 | G25: =$B$4*(((1-(1+F25)^(-$B$5*$B$6)))/F25) -> 25002.344 | I25: =ABS($F$11-K25) -> 79532.029 | J25: 0.005 | K25: =($B$4*(1+J25)*(((1+J25)^($B$6*$B$5))-1))/J25 -> 31740.6 | M25: =ABS($G$12-O25) -> 13808.994 | N25: 0.005 | O25: =($B$4*(1+N25)*(1-((1+N25)^(-$B$6*$B$5))))/N25 -> 25127.355 | Q25: =ABS($H$11-S25) -> 5140.7832 | R25: 0.005 | S25: =$B$3*((1+R25)^($B$6*$B$5)) -> 757.91343 | U25: =ABS($I$11-W25) -> 6838.2536 | V25: 0.005 | W25: =($B$4*(EXP(V25*$B$6)-1))/V25 -> 11786.211 | Y25: =ABS($I$12-AA25) -> 3434.2422 | Z25: 0.005 | AA25: =$B$4*(1-EXP(-Z25*$B$6))/Z25 -> 10732.119
A26: =ABS($D$11-C26) -> 73630.792 | B26: 0.006 | C26: =($B$4)*(((1+B26)^($B$6*$B$5))-1)/B26 -> 32343.141 | E26: =ABS($E$12-G26) -> 13659.458 | F26: 0.006 | G26: =$B$4*(((1-(1+F26)^(-$B$5*$B$6)))/F26) -> 24438.849 | I26: =ABS($F$11-K26) -> 78735.429 | J26: 0.006 | K26: =($B$4*(1+J26)*(((1+J26)^($B$6*$B$5))-1))/J26 -> 32537.2 | M26: =ABS($G$12-O26) -> 13267.122 | N26: 0.006 | O26: =($B$4*(1+N26)*(1-((1+N26)^(-$B$6*$B$5))))/N26 -> 24585.483 | Q26: =ABS($H$11-S26) -> 5104.6378 | R26: 0.006 | S26: =$B$3*((1+R26)^($B$6*$B$5)) -> 794.05885 | U26: =ABS($I$11-W26) -> 6725.3962 | V26: 0.006 | W26: =($B$4*(EXP(V26*$B$6)-1))/V26 -> 11899.068 | Y26: =ABS($I$12-AA26) -> 3335.8742 | Z26: 0.006 | AA26: =$B$4*(1-EXP(-Z26*$B$6))/Z26 -> 10633.751
A27: =ABS($D$11-C27) -> 72846.854 | B27: 0.007 | C27: =($B$4)*(((1+B27)^($B$6*$B$5))-1)/B27 -> 33127.078 | E27: =ABS($E$12-G27) -> 13113.501 | F27: 0.007 | G27: =$B$4*(((1-(1+F27)^(-$B$5*$B$6)))/F27) -> 23892.892 | I27: =ABS($F$11-K27) -> 77913.661 | J27: 0.007 | K27: =($B$4*(1+J27)*(((1+J27)^($B$6*$B$5))-1))/J27 -> 33358.968 | M27: =ABS($G$12-O27) -> 12741.781 | N27: 0.007 | O27: =($B$4*(1+N27)*(1-((1+N27)^(-$B$6*$B$5))))/N27 -> 24060.142 | Q27: =ABS($H$11-S27) -> 5066.8071 | R27: 0.007 | S27: =$B$3*((1+R27)^($B$6*$B$5)) -> 831.88955 | U27: =ABS($I$11-W27) -> 6611.1069 | V27: 0.007 | W27: =($B$4*(EXP(V27*$B$6)-1))/V27 -> 12013.358 | Y27: =ABS($I$12-AA27) -> 3238.7158 | Z27: 0.007 | AA27: =$B$4*(1-EXP(-Z27*$B$6))/Z27 -> 10536.593
A28: =ABS($D$11-C28) -> 72038.641 | B28: 0.008 | C28: =($B$4)*(((1+B28)^($B$6*$B$5))-1)/B28 -> 33935.291 | E28: =ABS($E$12-G28) -> 12584.45 | F28: 0.008 | G28: =$B$4*(((1-(1+F28)^(-$B$5*$B$6)))/F28) -> 23363.841 | I28: =ABS($F$11-K28) -> 77065.856 | J28: 0.008 | K28: =($B$4*(1+J28)*(((1+J28)^($B$6*$B$5))-1))/J28 -> 34206.774 | M28: =ABS($G$12-O28) -> 12232.391 | N28: 0.008 | O28: =($B$4*(1+N28)*(1-((1+N28)^(-$B$6*$B$5))))/N28 -> 23550.752 | Q28: =ABS($H$11-S28) -> 5027.2143 | R28: 0.008 | S28: =$B$3*((1+R28)^($B$6*$B$5)) -> 871.48233 | U28: =ABS($I$11-W28) -> 6495.3653 | V28: 0.008 | W28: =($B$4*(EXP(V28*$B$6)-1))/V28 -> 12129.099 | Y28: =ABS($I$12-AA28) -> 3142.7503 | Z28: 0.008 | AA28: =$B$4*(1-EXP(-Z28*$B$6))/Z28 -> 10440.627
A29: =ABS($D$11-C29) -> 71205.333 | B29: 0.009 | C29: =($B$4)*(((1+B29)^($B$6*$B$5))-1)/B29 -> 34768.599 | E29: =ABS($E$12-G29) -> 12071.701 | F29: 0.009 | G29: =$B$4*(((1-(1+F29)^(-$B$5*$B$6)))/F29) -> 22851.092 | I29: =ABS($F$11-K29) -> 76191.113 | J29: 0.009 | K29: =($B$4*(1+J29)*(((1+J29)^($B$6*$B$5))-1))/J29 -> 35081.517 | M29: =ABS($G$12-O29) -> 11738.391 | N29: 0.009 | O29: =($B$4*(1+N29)*(1-((1+N29)^(-$B$6*$B$5))))/N29 -> 23056.752 | Q29: =ABS($H$11-S29) -> 4985.7792 | R29: 0.009 | S29: =$B$3*((1+R29)^($B$6*$B$5)) -> 912.91739 | U29: =ABS($I$11-W29) -> 6378.1507 | V29: 0.009 | W29: =($B$4*(EXP(V29*$B$6)-1))/V29 -> 12246.314 | Y29: =ABS($I$12-AA29) -> 3047.9613 | Z29: 0.009 | AA29: =$B$4*(1-EXP(-Z29*$B$6))/Z29 -> 10345.838
A30: =ABS($D$11-C30) -> 70346.082 | B30: 0.01 | C30: =($B$4)*(((1+B30)^($B$6*$B$5))-1)/B30 -> 35627.85 | E30: =ABS($E$12-G30) -> 11574.672 | F30: 0.01 | G30: =$B$4*(((1-(1+F30)^(-$B$5*$B$6)))/F30) -> 22354.063 | I30: =ABS($F$11-K30) -> 75288.5 | J30: 0.01 | K30: =($B$4*(1+J30)*(((1+J30)^($B$6*$B$5))-1))/J30 -> 35984.129 | M30: =ABS($G$12-O30) -> 11259.243 | N30: 0.01 | O30: =($B$4*(1+N30)*(1-((1+N30)^(-$B$6*$B$5))))/N30 -> 22577.604 | Q30: =ABS($H$11-S30) -> 4942.4181 | R30: 0.01 | S30: =$B$3*((1+R30)^($B$6*$B$5)) -> 956.2785 | U30: =ABS($I$11-W30) -> 6259.442 | V30: 0.01 | W30: =($B$4*(EXP(V30*$B$6)-1))/V30 -> 12365.023 | Y30: =ABS($I$12-AA30) -> 2954.3323 | Z30: 0.01 | AA30: =$B$4*(1-EXP(-Z30*$B$6))/Z30 -> 10252.209
A31: =ABS($D$11-C31) -> 69460.01 | B31: 0.011 | C31: =($B$4)*(((1+B31)^($B$6*$B$5))-1)/B31 -> 36513.923 | E31: =ABS($E$12-G31) -> 11092.804 | F31: 0.011 | G31: =$B$4*(((1-(1+F31)^(-$B$5*$B$6)))/F31) -> 21872.196 | I31: =ABS($F$11-K31) -> 74357.053 | J31: 0.011 | K31: =($B$4*(1+J31)*(((1+J31)^($B$6*$B$5))-1))/J31 -> 36915.576 | M31: =ABS($G$12-O31) -> 10794.429 | N31: 0.011 | O31: =($B$4*(1+N31)*(1-((1+N31)^(-$B$6*$B$5))))/N31 -> 22112.79 | Q31: =ABS($H$11-S31) -> 4897.0435 | R31: 0.011 | S31: =$B$3*((1+R31)^($B$6*$B$5)) -> 1001.6532 | U31: =ABS($I$11-W31) -> 6139.218 | V31: 0.011 | W31: =($B$4*(EXP(V31*$B$6)-1))/V31 -> 12485.247 | Y31: =ABS($I$12-AA31) -> 2861.8474 | Z31: 0.011 | AA31: =$B$4*(1-EXP(-Z31*$B$6))/Z31 -> 10159.724
A32: =ABS($D$11-C32) -> 68546.207 | B32: 0.012 | C32: =($B$4)*(((1+B32)^($B$6*$B$5))-1)/B32 -> 37427.726 | E32: =ABS($E$12-G32) -> 10625.561 | F32: 0.012 | G32: =$B$4*(((1-(1+F32)^(-$B$5*$B$6)))/F32) -> 21404.952 | I32: =ABS($F$11-K32) -> 73395.771 | J32: 0.012 | K32: =($B$4*(1+J32)*(((1+J32)^($B$6*$B$5))-1))/J32 -> 37876.858 | M32: =ABS($G$12-O32) -> 10343.451 | N32: 0.012 | O32: =($B$4*(1+N32)*(1-((1+N32)^(-$B$6*$B$5))))/N32 -> 21661.812 | Q32: =ABS($H$11-S32) -> 4849.5639 | R32: 0.012 | S32: =$B$3*((1+R32)^($B$6*$B$5)) -> 1049.1327 | U32: =ABS($I$11-W32) -> 6017.4571 | V32: 0.012 | W32: =($B$4*(EXP(V32*$B$6)-1))/V32 -> 12607.008 | Y32: =ABS($I$12-AA32) -> 2770.4908 | Z32: 0.012 | AA32: =$B$4*(1-EXP(-Z32*$B$6))/Z32 -> 10068.368
A33: =ABS($D$11-C33) -> 67603.734 | B33: 0.013 | C33: =($B$4)*(((1+B33)^($B$6*$B$5))-1)/B33 -> 38370.199 | E33: =ABS($E$12-G33) -> 10172.425 | F33: 0.013 | G33: =$B$4*(((1-(1+F33)^(-$B$5*$B$6)))/F33) -> 20951.816 | I33: =ABS($F$11-K33) -> 72403.618 | J33: 0.013 | K33: =($B$4*(1+J33)*(((1+J33)^($B$6*$B$5))-1))/J33 -> 38869.012 | M33: =ABS($G$12-O33) -> 9905.8289 | N33: 0.013 | O33: =($B$4*(1+N33)*(1-((1+N33)^(-$B$6*$B$5))))/N33 -> 21224.19 | Q33: =ABS($H$11-S33) -> 4799.884 | R33: 0.013 | S33: =$B$3*((1+R33)^($B$6*$B$5)) -> 1098.8126 | U33: =ABS($I$11-W33) -> 5894.1371 | V33: 0.013 | W33: =($B$4*(EXP(V33*$B$6)-1))/V33 -> 12730.328 | Y33: =ABS($I$12-AA33) -> 2680.2469 | Z33: 0.013 | AA33: =$B$4*(1-EXP(-Z33*$B$6))/Z33 -> 9978.1239
A34: =ABS($D$11-C34) -> 66631.616 | B34: 0.014 | C34: =($B$4)*(((1+B34)^($B$6*$B$5))-1)/B34 -> 39342.317 | E34: =ABS($E$12-G34) -> 9732.9004 | F34: 0.014 | G34: =$B$4*(((1-(1+F34)^(-$B$5*$B$6)))/F34) -> 20512.292 | I34: =ABS($F$11-K34) -> 71379.52 | J34: 0.014 | K34: =($B$4*(1+J34)*(((1+J34)^($B$6*$B$5))-1))/J34 -> 39893.11 | M34: =ABS($G$12-O34) -> 9481.1029 | N34: 0.014 | O34: =($B$4*(1+N34)*(1-((1+N34)^(-$B$6*$B$5))))/N34 -> 20799.464 | Q34: =ABS($H$11-S34) -> 4747.9042 | R34: 0.014 | S34: =$B$3*((1+R34)^($B$6*$B$5)) -> 1150.7924 | U34: =ABS($I$11-W34) -> 5769.2358 | V34: 0.014 | W34: =($B$4*(EXP(V34*$B$6)-1))/V34 -> 12855.229 | Y34: =ABS($I$12-AA34) -> 2591.1003 | Z34: 0.014 | AA34: =$B$4*(1-EXP(-Z34*$B$6))/Z34 -> 9888.9773
A35: =ABS($D$11-C35) -> 65628.845 | B35: 0.015 | C35: =($B$4)*(((1+B35)^($B$6*$B$5))-1)/B35 -> 40345.088 | E35: =ABS($E$12-G35) -> 9306.51 | F35: 0.015 | G35: =$B$4*(((1-(1+F35)^(-$B$5*$B$6)))/F35) -> 20085.901 | I35: =ABS($F$11-K35) -> 70322.365 | J35: 0.015 | K35: =($B$4*(1+J35)*(((1+J35)^($B$6*$B$5))-1))/J35 -> 40950.264 | M35: =ABS($G$12-O35) -> 9068.8289 | N35: 0.015 | O35: =($B$4*(1+N35)*(1-((1+N35)^(-$B$6*$B$5))))/N35 -> 20387.19 | Q35: =ABS($H$11-S35) -> 4693.5203 | R35: 0.015 | S35: =$B$3*((1+R35)^($B$6*$B$5)) -> 1205.1763 | U35: =ABS($I$11-W35) -> 5642.7305 | V35: 0.015 | W35: =($B$4*(EXP(V35*$B$6)-1))/V35 -> 12981.734 | Y35: =ABS($I$12-AA35) -> 2503.036 | Z35: 0.015 | AA35: =$B$4*(1-EXP(-Z35*$B$6))/Z35 -> 9800.913
... A1020: =ABS($D$11-C1020) -> 7.5820929e+16 | B1020: 1 | C1020: =($B$4)*(((1+B1020)^($B$6*$B$5))-1)/B1020 -> 7.5820929e+16 | E1020: =ABS($E$12-G1020) -> 10179.391 | F1020: 1 | G1020: =$B$4*(((1-(1+F1020)^(-$B$5*$B$6)))/F1020) -> 600 | I1020: =ABS($F$11-K1020) -> 1.5164186e+17 | J1020: 1 | K1020: =($B$4*(1+J1020)*(((1+J1020)^($B$6*$B$5))-1))/J1020 -> 1.5164186e+17 | M1020: =ABS($G$12-O1020) -> 10118.361 | N1020: 1 | O1020: =($B$4*(1+N1020)*(1-((1+N1020)^(-$B$6*$B$5))))/N1020 -> 1200 | Q1020: =ABS($H$11-S1020) -> 7.5820929e+16 | R1020: 1 | S1020: =$B$3*((1+R1020)^($B$6*$B$5)) -> 7.5820929e+16 | U1020: =ABS($I$11-W1020) -> 8.2394144e+10 | V1020: 1 | W1020: =($B$4*(EXP(V1020*$B$6)-1))/V1020 -> 8.2394163e+10 | Y1020: =ABS($I$12-AA1020) -> 6697.877 | Z1020: 1 | AA1020: =$B$4*(1-EXP(-Z1020*$B$6))/Z1020 -> 600

Sheet Assignment3 (User Interface)
A1: ANNUITIES CALCULATOR | R1: Exact Year | S1: Future Value in Arrears | T1: Future Value
A2: Given: | B2: Continuous Future (normal) | I2: Requested Value: | J2: Future Value | R2: Dates | S2: Present Value in Arrears | T2: Present Value
S3: Future Value in Advance | T3: Annuity
I4: Value: | J4: =IF(AND(B2=S1,J2=T1),'Assignment3 (Back End)'!D11,IF(AND(B2=S1,J2=T2),'Assignment3 (Back End)'!D12,IF(AND(B2=S1,J2=T3),'Assignment3 (Back End)'!D13,IF(AND(B2=S1,J2=T4),'Assignment3 (Back End)'!D15,IF(AND(B2=S1,J2=T5),'Assignment3 (Back End)'!D14,IF(AND(B2=S1,J2=T6),TEXT('Assignment3 (Back End)'!D16,"0.0000%"),IF(AND(B2=S2,J2=T1),'Assignment3 (Back End)'!E11,IF(AND(B2=S2,J2=T2),'Assignment3 (Back End)'!E12,IF(AND(B2=S2,J2=T3),'Assignment3 (Back End)'!E13,IF(AND(B2=S2,J2=T4),'Assignment3 (Back End)'!E15,IF(AND(B2=S2,J2=T5),'Assignment3 (Back End)'!E14,IF(AND(B2=S2,J2=T6),TEXT('Assignment3 (Back End)'!E16,"0.0000%"),IF(AND(B2=S3,J2=T1),'Assignment3 (Back End)'!F11,IF(AND(B2=S3,J2=T2),'Assignment3 (Back End)'!F12,IF(AND(B2=S3,J2=T3),'Assignment3 (Back End)'!F13,IF(AND(B2=S3,J2=T4),'Assignment3 (Back End)'!F15,IF(AND(B2=S3,J2=T5),'Assignment3 (Back End)'!F14,IF(AND(B2=S3,J2=T6),TEXT('Assignment3 (Back End)'!F16,"0.0000%"),IF(AND(B2=S4,J2=T1),'Assignment3 (Back End)'!G11,IF(AND(B2=S4,J2=T2),'Assignment3 (Back End)'!G12,IF(AND(B2=S4,J2=T3),'Assignment3 (Back End)'!G13,IF(AND(B2=S4,J2=T4),'Assignment3 (Back End)'!G15,IF(AND(B2=S4,J2=T5),'Assignment3 (Back End)'!G14,IF(AND(B2=S4,J2=T6),TEXT('Assignment3 (Back End)'!G16,"0.0000%"),IF(AND(B2=S5,J2=T1),'Assignment3 (Back End)'!H11,IF(AND(B2=S5,J2=T2),'Assignment3 (Back End)'!H12,IF(AND(B2=S5,J2=T4),'Assignment3 (Back End)'!H15,IF(AND(B2=S5,J2=T5),'Assignment3 (Back End)'!H14,IF(AND(B2=S5,J2=T6),TEXT('Assignment3 (Back End)'!H16,"0.0000%"),IF(AND(B2=S6,J2=T1),'Assignment3 (Back End)'!I11,IF(AND(B2=S6,J2=T2),'Assignment3 (Back End)'!I12,IF(AND(B2=S6,J2=T3),'Assignment3 (Back End)'!I13,IF(AND(B2=S6,J2=T4),'Assignment3 (Back End)'!I15,IF(AND(B2=S6,J2=T5),'Assignment3 (Back End)'!I14,IF(AND(B2=S6,J2=T6),TEXT('Assignment3 (Back End)'!I16,"0.0000%"),IF(AND(B2=S7,J2=T1),'Assignment3 (Back End)'!I11,IF(AND(B2=S7,J2=T2),'Assignment3 (Back End)'!J12,IF(AND(B2=S7,J2=T3),'Assignment3 (Back End)'!J13,IF(AND(B2=S7,J2=T4),'Assignment3 (Back End)'!J15,IF(AND(B2=S7,J2=T5),'Assignment3 (Back End)'!J14,IF(AND(B2=S7,J2=T6),TEXT('Assignment3 (Back End)'!J16,"0.0000%"),"More work to b edone"))))))))))))))))))))))))))))))))))))))))) -> 18624.465 | S4: Present Value in advance | T4: Period
S5: Given Future value and Present value | T5: Years
I6: Real Future Value | J6: =IF(J2=T1, J4*(1+5%)^(-'Assignment3 (Back End)'!B6), " ") -> 7465.2073 | S6: Continuous Future (normal) | T6: Interest
A7: Given Values: | S7: Continuous Present
A8: Future Value | B8: 6600
A9: Present Value | B9: 600 | I9: To Convert Interest Rates:
A10: Annuity | B10: 600
A11: Period | B11: 2.5 | I11: For Single invetments
A12: Years By: | B12: Dates
A13: Years: | B13: =IF(B12=R1,D14,IF(B12=R2,B14)) -> 18.737851 | I13: Home
A14: Dates (yyyy/mm/dd): | B14: =(B16 - B15)/ 365.25 -> 18.737851 | C14: Exact Date: | D14: 3
A15: Start: | B15: 37327
A16: End: | B16: 44171
A17: Interest | B17: 0.05
A19: ANNUITY GRAPHS
AH20: Arrears Annuity
A21: Annuity Type: | B21: Arears Annuity | I21: Annuity Type: | J21: Advance Annuity | AH21: Continuous
A23: Periods(Years) | B23: Arrears Annuity | I23: Periods(Years) | J23: =J21 -> Advance Annuity
A24: 1 | B24: =($B$10)*(((1+$B$17)^(A24))-1)/$B$17 -> 600 | I24: 1 | J24: =($B$10*(1+$B$17)*(((1+$B$17)^(I24))-1))/$B$17 -> 630
A25: 2 | B25: =($B$10)*(((1+$B$17)^(A25))-1)/$B$17 -> 1230 | I25: 2 | J25: =($B$10*(1+$B$17)*(((1+$B$17)^(I25))-1))/$B$17 -> 1291.5
A26: 3 | B26: =($B$10)*(((1+$B$17)^(A26))-1)/$B$17 -> 1891.5 | I26: 3 | J26: =($B$10*(1+$B$17)*(((1+$B$17)^(I26))-1))/$B$17 -> 1986.075
A27: 4 | B27: =($B$10)*(((1+$B$17)^(A27))-1)/$B$17 -> 2586.075 | I27: 4 | J27: =($B$10*(1+$B$17)*(((1+$B$17)^(I27))-1))/$B$17 -> 2715.3787
A28: 5 | B28: =($B$10)*(((1+$B$17)^(A28))-1)/$B$17 -> 3315.3788 | I28: 5 | J28: =($B$10*(1+$B$17)*(((1+$B$17)^(I28))-1))/$B$17 -> 3481.1477
A29: 6 | B29: =($B$10)*(((1+$B$17)^(A29))-1)/$B$17 -> 4081.1477 | I29: 6 | J29: =($B$10*(1+$B$17)*(((1+$B$17)^(I29))-1))/$B$17 -> 4285.2051
A30: 7 | B30: =($B$10)*(((1+$B$17)^(A30))-1)/$B$17 -> 4885.2051 | I30: 7 | J30: =($B$10*(1+$B$17)*(((1+$B$17)^(I30))-1))/$B$17 -> 5129.4653
A31: 8 | B31: =($B$10)*(((1+$B$17)^(A31))-1)/$B$17 -> 5729.4653 | I31: 8 | J31: =($B$10*(1+$B$17)*(((1+$B$17)^(I31))-1))/$B$17 -> 6015.9386
A32: 9 | B32: =($B$10)*(((1+$B$17)^(A32))-1)/$B$17 -> 6615.9386 | I32: 9 | J32: =($B$10*(1+$B$17)*(((1+$B$17)^(I32))-1))/$B$17 -> 6946.7355
A33: 10 | B33: =($B$10)*(((1+$B$17)^(A33))-1)/$B$17 -> 7546.7355 | I33: 10 | J33: =($B$10*(1+$B$17)*(((1+$B$17)^(I33))-1))/$B$17 -> 7924.0723

Sheet Assignment4 (Back End)
A1: Givens
A2: Loan Amount | B2: ='Assignment4 (User Interface)'!B4 -> 70000
A3: Payment | B3: ='Assignment4 (User Interface)'!B5 -> 3950.1909
A4: Years | B4: ='Assignment4 (User Interface)'!B6 -> 9.5
A5: Periods per year | B5: ='Assignment4 (User Interface)'!B7 -> 2
A6: Effective Periodic or nominal interest rate | B6: ='Assignment4 (User Interface)'!B8 -> 0.0016515813 | G6: Arrears | H6: Advance
A7: Specific time (Year) | B7: ='Assignment4 (User Interface)'!B9*B5 -> 10 | F7: Loan amount | G7: =($B$3*(1-((1+$B$6)^(-$B$4*$B$5))))/$B$6 -> 73828.258 | H7: =(($B$3*(1+$B$6))*(1-((1+$B$6)^(-$B$4*$B$5))))/$B$6 -> 73950.191
A8: Pecific year in periods | B8: ='Assignment4 (User Interface)'!B10 -> 12 | F8: Payment | G8: =$B$2/((1-((1+$B$6)^(-$B$4*$B$5)))/$B$6) -> 3745.3595 | H8: =$B$2*(1+B6)/((1-((1+$B$6)^(-$B$4*$B$5)))/$B$6) -> 3751.5453
A9: Number of Payment (K) | B9: ='Assignment4 (User Interface)'!B11 -> 1 | F9: Period to repay | G9: =-LN(1-($B$2*$B$6)/$B$3)/LN(1+$B$6) -> 18 | H9: =-LN(1-($B$2*$B$6)/$B$3*(1+B6))/LN(1+$B$6) -> 18.030175
A10: Start Period (Interest/capital) | B10: ='Assignment4 (User Interface)'!B12 -> 1 | F10: Balance at specific time of the year | G10: =VLOOKUP(IF(B7=0, B8,B7),'Assignment4 (User Interface)'!A21:H532,6,FALSE) -> 31367.948 | H10: =VLOOKUP(IF(B7=0, B8,B7),'Assignment4 (User Interface)'!L21:T761,7,FALSE) -> 31302.221
A11: End Period (Interest/Capital) | B11: ='Assignment4 (User Interface)'!B13 -> 2 | F11: Interest component of payment k | G11: =VLOOKUP(B8,'Assignment4 (User Interface)'!A21:H1050,3,FALSE) -> 45.368219 | H11: =VLOOKUP(IF(B7=0, B8,B7), 'Assignment4 (User Interface)'!L21:T761,5,FALSE) -> 58.041121
F12: Capital component of payment k | G12: =VLOOKUP(IF(B7=0, B8,B7), 'Assignment4 (User Interface)'!A21:H891,5,FALSE) -> 3891.9563 | H12: =VLOOKUP(IF(B7=0, B8,B7), 'Assignment4 (User Interface)'!L21:T667,6,FALSE) -> 3892.1498
F13: Interest from payment X1 to X2 | G13: =SUM(INDEX('Assignment4 (User Interface)'!C22:C700, MATCH( 'Assignment4 (Back End)'!B10, 'Assignment4 (User Interface)'!A22:A607, 0)) : INDEX('Assignment4 (User Interface)'!C22:C607, MATCH('Assignment4 (Back End)'!B11, 'Assignment4 (User Interface)'!A22:A607, 0))) -> 224.88826 | H13: =SUM(INDEX('Assignment4 (User Interface)'!P22:P700, MATCH( 'Assignment4 (Back End)'!B10, 'Assignment4 (User Interface)'!L22:L607, 0)) : INDEX('Assignment4 (User Interface)'!P22:P607, MATCH('Assignment4 (Back End)'!B11, 'Assignment4 (User Interface)'!L22:L607, 0))) -> 109.08663
F14: Capital from payment X1 to X2 | G14: =SUM(INDEX('Assignment4 (User Interface)'!E22:E700, MATCH( 'Assignment4 (Back End)'!B10, 'Assignment4 (User Interface)'!A22:A607, 0)) : INDEX('Assignment4 (User Interface)'!E22:E607, MATCH('Assignment4 (Back End)'!B11, 'Assignment4 (User Interface)'!A22:A607, 0))) -> 7675.4936 | H14: =SUM(INDEX('Assignment4 (User Interface)'!Q22:Q700, MATCH( 'Assignment4 (Back End)'!B10, 'Assignment4 (User Interface)'!L22:L607, 0)) : INDEX('Assignment4 (User Interface)'!Q22:Q607, MATCH('Assignment4 (Back End)'!B11, 'Assignment4 (User Interface)'!L22:L607, 0))) -> 7791.2952
F15: Last payment | G15: =VLOOKUP(B4*B5, 'Assignment4 (User Interface)'!A22:H961,2,FALSE)*(1+B6) -> -8.1716414e-10 | H15: =VLOOKUP(B4*B5, 'Assignment4 (User Interface)'!L21:T767,4,FALSE) -> -4069.2872
F16: Total Interest | G16: {=LOOKUP(2, 1/('Assignment4 (User Interface)'!G22:G607), 'Assignment4 (User Interface)'!G22:G607)} -> 1103.4367 | H16: {=LOOKUP(2, 1/('Assignment4 (User Interface)'!S22:S607), 'Assignment4 (User Interface)'!S22:S607)} -> 984.34044
F17: Total Capital | G17: {=LOOKUP(2, 1/('Assignment4 (User Interface)'!H22:H607), 'Assignment4 (User Interface)'!H22:H607)} -> 73950.191 | H17: {=LOOKUP(2, 1/('Assignment4 (User Interface)'!T22:T607), 'Assignment4 (User Interface)'!T22:T607)} -> 74069.287

Sheet Assignment4 (User Interface)
A1: LOANS / WITHDRAWALS | M1: Comparison Graphs
AD2: Loan amount | AE2: Arrears
A3: Givens | E3: Unkowns | AD3: Payment | AE3: Advance
A4: Loan Amount | B4: 70000 | E4: Loan Type: | F4: Arrears | H4: Loan component(Variable): | I4: Period to repay | AD4: Period to repay
A5: Payment | B5: 3950.1909 | AD5: Balance at specific time of the year
A6: Years | B6: 9.5 | AD6: Interest component of payment k
A7: Periods per year | B7: 2 | AD7: Capital component of payment k
A8: Effective Periodic interest rate | B8: 0.0016515813 | H8: VALUE | I8: =IF(AND(F4=J26,I4=I26),'Assignment4 (Back End)'!G7,IF(AND(F4=J26,I4=I27),'Assignment4 (Back End)'!G8,IF(AND(F4=J26,I4=I28),'Assignment4 (Back End)'!G9,IF(AND(F4=J26,I4=I29),'Assignment4 (Back End)'!G10,IF(AND(F4=J26,I4=I30),'Assignment4 (Back End)'!G11,IF(AND(F4=J26,I4=I31),'Assignment4 (Back End)'!G12,IF(AND(F4=J26,I4=I32),'Assignment4 (Back End)'!G13,IF(AND(F4=J26,I4=I33),'Assignment4 (Back End)'!G14,IF(AND(F4=J26,I4=I34),'Assignment4 (Back End)'!G15,IF(AND(F4=J27,I4=I26),'Assignment4 (Back End)'!H7,IF(AND(F4=J27,I4=I27),'Assignment4 (Back End)'!H8,IF(AND(F4=J27,I4=I28),'Assignment4 (Back End)'!H9,IF(AND(F4=J27,I4=I29),'Assignment4 (Back End)'!H10,IF(AND(F4=J27,I4=I30),'Assignment4 (Back End)'!H11,IF(AND(F4=J27,I4=I31),'Assignment4 (Back End)'!H12,IF(AND(F4=J27,I4=I32),'Assignment4 (Back End)'!H13,IF(AND(F4=J27,I4=I33),'Assignment4 (Back End)'!H14,IF(AND(F4=J27,I4=I34),'Assignment4 (Back End)'!H15,"Not done yet")))))))))))))))))) -> 18 | AD8: Interest from payment X1 to X2
A9: Specific time (Year) | B9: 5 | AD9: Capital from payment X1 to X2
A10: Specific time (Periods) | B10: 12 | AD10: Last payment(Balance)
A11: Number of Payment (K) | B11: 1 | H11: Real Future Value | I11: =IF(I4=I24, I8*(1+5%)^(-B6), " ")
A12: Start period | B12: 1
A13: End period | B13: 2
E14: To Convert Interest Rates:
E16: Home
AF18: Arrears | AI18: Advance
AF19: Period | AG19: Balance at end | AI19: Period | AJ19: Balance at end
A20: Amortization table (Arrears) | L20: Amortization table (Advance) | AF20: 0 | AG20: =$B$22 -> 70000 | AI20: 0 | AJ20: =M22 -> 70000
A21: Period | B21: Balance at Start | C21: Interest | D21: Payment | E21: Capital | F21: Balance at end | G21: Interest so far | H21: Capital so far | L21: Period | M21: Balance at Start (Before payment) | N21: Payment | O21: Balance at start (after payment) | P21: Interest | Q21: Capital | R21: Balance at the end | S21: Interest so far | T21: Capital so far | AF21: 1 | AG21: =F22 -> 66165.42 | AI21: =L22 -> 1 | AJ21: =R22 -> 66158.896
A22: 1 | B22: =B4 -> 70000 | C22: =$B$8*B22 -> 115.61069 | D22: =$B$5 -> 3950.1909 | E22: =D22-C22 -> 3834.5802 | F22: =B22-E22 -> 66165.42 | G22: =C22 -> 115.61069 | H22: =E22 -> 3834.5802 | L22: 1 | M22: =B4 -> 70000 | N22: =$B$5 -> 3950.1909 | O22: =M22-N22 -> 66049.809 | P22: 0 | Q22: =N22-P22 -> 3950.1909 | R22: =O22*(1+$B$8) -> 66158.896 | S22: =P22 -> 0 | T22: =Q22 -> 3950.1909 | AF22: =IF(AF21<($B$6*$B$7),AF21+1,"") -> 2 | AG22: =F23 -> 62324.506 | AI22: =L23 -> 2 | AJ22: =R23 -> 62311.448
A23: =IF(A22<($B$6*$B$7),A22+1,"") -> 2 | B23: =IF(A23="","",F22) -> 66165.42 | C23: =IF(A23="","",(B23*$B$8)) -> 109.27757 | D23: =IF(A23="","", $B$5) -> 3950.1909 | E23: =IF(D23="","",(D23-C23)) -> 3840.9134 | F23: =IF(A23="","", B23-E23) -> 62324.506 | G23: =IF(A23="","", (G22+C23)) -> 224.88826 | H23: =IF(A23="","",(H22+E23)) -> 7675.4936 | L23: =IF(L22<($B$6*$B$7),L22+1,"") -> 2 | M23: =IF(L23="", "", R22) -> 66158.896 | N23: =IF(L23="","",$B$5) -> 3950.1909 | O23: =IF(L23="","",M23-N23) -> 62208.705 | P23: =IF(L23="","",O22*$B$8) -> 109.08663 | Q23: =IF(L23="","",N23-P23) -> 3841.1043 | R23: =IF(L23="","",O23*(1+$B$8)) -> 62311.448 | S23: =IF(L23="","",S22+P23) -> 109.08663 | T23: =IF(L23="","",Q23+T22) -> 7791.2952 | AF23: =IF(AF22<($B$6*$B$7),AF22+1,"") -> 3 | AG23: =F24 -> 58477.249 | AI23: =L24 -> 3 | AJ23: =R24 -> 58457.645
A24: =IF(A23<($B$6*$B$7),A23+1,"") -> 3 | B24: =IF(A24="","",F23) -> 62324.506 | C24: =IF(A24="","",(B24*$B$8)) -> 102.93399 | D24: =IF(A24="","", $B$5) -> 3950.1909 | E24: =IF(D24="","",(D24-C24)) -> 3847.2569 | F24: =IF(A24="","", B24-E24) -> 58477.249 | G24: =IF(A24="","", (G23+C24)) -> 327.82225 | H24: =IF(A24="","",(H23+E24)) -> 11522.751 | I24: Future | L24: =IF(L23<($B$6*$B$7),L23+1,"") -> 3 | M24: =IF(L24="", "", R23) -> 62311.448 | N24: =IF(L24="","",$B$5) -> 3950.1909 | O24: =IF(L24="","",M24-N24) -> 58361.257 | P24: =IF(L24="","",O23*$B$8) -> 102.74273 | Q24: =IF(L24="","",N24-P24) -> 3847.4482 | R24: =IF(L24="","",O24*(1+$B$8)) -> 58457.645 | S24: =IF(L24="","",S23+P24) -> 211.82936 | T24: =IF(L24="","",Q24+T23) -> 11638.743 | AF24: =IF(AF23<($B$6*$B$7),AF23+1,"") -> 4 | AG24: =F25 -> 54623.638 | AI24: =L25 -> 4 | AJ24: =R25 -> 54597.477
A25: =IF(A24<($B$6*$B$7),A24+1,"") -> 4 | B25: =IF(A25="","",F24) -> 58477.249 | C25: =IF(A25="","",(B25*$B$8)) -> 96.579932 | D25: =IF(A25="","", $B$5) -> 3950.1909 | E25: =IF(D25="","",(D25-C25)) -> 3853.611 | F25: =IF(A25="","", B25-E25) -> 54623.638 | G25: =IF(A25="","", (G24+C25)) -> 424.40218 | H25: =IF(A25="","",(H24+E25)) -> 15376.362 | L25: =IF(L24<($B$6*$B$7),L24+1,"") -> 4 | M25: =IF(L25="", "", R24) -> 58457.645 | N25: =IF(L25="","",$B$5) -> 3950.1909 | O25: =IF(L25="","",M25-N25) -> 54507.454 | P25: =IF(L25="","",O24*$B$8) -> 96.38836 | Q25: =IF(L25="","",N25-P25) -> 3853.8026 | R25: =IF(L25="","",O25*(1+$B$8)) -> 54597.477 | S25: =IF(L25="","",S24+P25) -> 308.21772 | T25: =IF(L25="","",Q25+T24) -> 15492.546 | AF25: =IF(AF24<($B$6*$B$7),AF24+1,"") -> 5 | AG25: =F26 -> 50763.663 | AI25: =L26 -> 5 | AJ25: =R26 -> 50730.935
A26: =IF(A25<($B$6*$B$7),A25+1,"") -> 5 | B26: =IF(A26="","",F25) -> 54623.638 | C26: =IF(A26="","",(B26*$B$8)) -> 90.21538 | D26: =IF(A26="","", $B$5) -> 3950.1909 | E26: =IF(D26="","",(D26-C26)) -> 3859.9755 | F26: =IF(A26="","", B26-E26) -> 50763.663 | G26: =IF(A26="","", (G25+C26)) -> 514.61756 | H26: =IF(A26="","",(H25+E26)) -> 19236.337 | I26: Loan amount | J26: Arrears | L26: =IF(L25<($B$6*$B$7),L25+1,"") -> 5 | M26: =IF(L26="", "", R25) -> 54597.477 | N26: =IF(L26="","",$B$5) -> 3950.1909 | O26: =IF(L26="","",M26-N26) -> 50647.287 | P26: =IF(L26="","",O25*$B$8) -> 90.023492 | Q26: =IF(L26="","",N26-P26) -> 3860.1674 | R26: =IF(L26="","",O26*(1+$B$8)) -> 50730.935 | S26: =IF(L26="","",S25+P26) -> 398.24122 | T26: =IF(L26="","",Q26+T25) -> 19352.713 | AF26: =IF(AF25<($B$6*$B$7),AF25+1,"") -> 6 | AG26: =F27 -> 46897.312 | AI26: =L27 -> 6 | AJ26: =R27 -> 46858.006
A27: =IF(A26<($B$6*$B$7),A26+1,"") -> 6 | B27: =IF(A27="","",F26) -> 50763.663 | C27: =IF(A27="","",(B27*$B$8)) -> 83.840316 | D27: =IF(A27="","", $B$5) -> 3950.1909 | E27: =IF(D27="","",(D27-C27)) -> 3866.3506 | F27: =IF(A27="","", B27-E27) -> 46897.312 | G27: =IF(A27="","", (G26+C27)) -> 598.45788 | H27: =IF(A27="","",(H26+E27)) -> 23102.688 | I27: Payment | J27: Advance | L27: =IF(L26<($B$6*$B$7),L26+1,"") -> 6 | M27: =IF(L27="", "", R26) -> 50730.935 | N27: =IF(L27="","",$B$5) -> 3950.1909 | O27: =IF(L27="","",M27-N27) -> 46780.744 | P27: =IF(L27="","",O26*$B$8) -> 83.648111 | Q27: =IF(L27="","",N27-P27) -> 3866.5428 | R27: =IF(L27="","",O27*(1+$B$8)) -> 46858.006 | S27: =IF(L27="","",S26+P27) -> 481.88933 | T27: =IF(L27="","",Q27+T26) -> 23219.256 | AF27: =IF(AF26<($B$6*$B$7),AF26+1,"") -> 7 | AG27: =F28 -> 43024.576 | AI27: =L28 -> 7 | AJ27: =R28 -> 42978.681
A28: =IF(A27<($B$6*$B$7),A27+1,"") -> 7 | B28: =IF(A28="","",F27) -> 46897.312 | C28: =IF(A28="","",(B28*$B$8)) -> 77.454724 | D28: =IF(A28="","", $B$5) -> 3950.1909 | E28: =IF(D28="","",(D28-C28)) -> 3872.7362 | F28: =IF(A28="","", B28-E28) -> 43024.576 | G28: =IF(A28="","", (G27+C28)) -> 675.9126 | H28: =IF(A28="","",(H27+E28)) -> 26975.424 | I28: Period to repay | L28: =IF(L27<($B$6*$B$7),L27+1,"") -> 7 | M28: =IF(L28="", "", R27) -> 46858.006 | N28: =IF(L28="","",$B$5) -> 3950.1909 | O28: =IF(L28="","",M28-N28) -> 42907.815 | P28: =IF(L28="","",O27*$B$8) -> 77.262202 | Q28: =IF(L28="","",N28-P28) -> 3872.9287 | R28: =IF(L28="","",O28*(1+$B$8)) -> 42978.681 | S28: =IF(L28="","",S27+P28) -> 559.15153 | T28: =IF(L28="","",Q28+T27) -> 27092.185 | AF28: =IF(AF27<($B$6*$B$7),AF27+1,"") -> 8 | AG28: =F29 -> 39145.444 | AI28: =L29 -> 8 | AJ28: =R29 -> 39092.949
A29: =IF(A28<($B$6*$B$7),A28+1,"") -> 8 | B29: =IF(A29="","",F28) -> 43024.576 | C29: =IF(A29="","",(B29*$B$8)) -> 71.058585 | D29: =IF(A29="","", $B$5) -> 3950.1909 | E29: =IF(D29="","",(D29-C29)) -> 3879.1323 | F29: =IF(A29="","", B29-E29) -> 39145.444 | G29: =IF(A29="","", (G28+C29)) -> 746.97119 | H29: =IF(A29="","",(H28+E29)) -> 30854.556 | I29: Balance at specific time of the year | L29: =IF(L28<($B$6*$B$7),L28+1,"") -> 8 | M29: =IF(L29="", "", R28) -> 42978.681 | N29: =IF(L29="","",$B$5) -> 3950.1909 | O29: =IF(L29="","",M29-N29) -> 39028.49 | P29: =IF(L29="","",O28*$B$8) -> 70.865745 | Q29: =IF(L29="","",N29-P29) -> 3879.3252 | R29: =IF(L29="","",O29*(1+$B$8)) -> 39092.949 | S29: =IF(L29="","",S28+P29) -> 630.01727 | T29: =IF(L29="","",Q29+T28) -> 30971.51 | AF29: =IF(AF28<($B$6*$B$7),AF28+1,"") -> 9 | AG29: =F30 -> 35259.905 | AI29: =L30 -> 9 | AJ29: =R30 -> 35200.799
A30: =IF(A29<($B$6*$B$7),A29+1,"") -> 9 | B30: =IF(A30="","",F29) -> 39145.444 | C30: =IF(A30="","",(B30*$B$8)) -> 64.651883 | D30: =IF(A30="","", $B$5) -> 3950.1909 | E30: =IF(D30="","",(D30-C30)) -> 3885.539 | F30: =IF(A30="","", B30-E30) -> 35259.905 | G30: =IF(A30="","", (G29+C30)) -> 811.62307 | H30: =IF(A30="","",(H29+E30)) -> 34740.095 | I30: Interest component of payment k | L30: =IF(L29<($B$6*$B$7),L29+1,"") -> 9 | M30: =IF(L30="", "", R29) -> 39092.949 | N30: =IF(L30="","",$B$5) -> 3950.1909 | O30: =IF(L30="","",M30-N30) -> 35142.758 | P30: =IF(L30="","",O29*$B$8) -> 64.458724 | Q30: =IF(L30="","",N30-P30) -> 3885.7322 | R30: =IF(L30="","",O30*(1+$B$8)) -> 35200.799 | S30: =IF(L30="","",S29+P30) -> 694.476 | T30: =IF(L30="","",Q30+T29) -> 34857.242 | AF30: =IF(AF29<($B$6*$B$7),AF29+1,"") -> 10 | AG30: =F31 -> 31367.948 | AI30: =L31 -> 10 | AJ30: =R31 -> 31302.221
A31: =IF(A30<($B$6*$B$7),A30+1,"") -> 10 | B31: =IF(A31="","",F30) -> 35259.905 | C31: =IF(A31="","",(B31*$B$8)) -> 58.234599 | D31: =IF(A31="","", $B$5) -> 3950.1909 | E31: =IF(D31="","",(D31-C31)) -> 3891.9563 | F31: =IF(A31="","", B31-E31) -> 31367.948 | G31: =IF(A31="","", (G30+C31)) -> 869.85767 | H31: =IF(A31="","",(H30+E31)) -> 38632.052 | I31: Capital component of payment k | L31: =IF(L30<($B$6*$B$7),L30+1,"") -> 10 | M31: =IF(L31="", "", R30) -> 35200.799 | N31: =IF(L31="","",$B$5) -> 3950.1909 | O31: =IF(L31="","",M31-N31) -> 31250.608 | P31: =IF(L31="","",O30*$B$8) -> 58.041121 | Q31: =IF(L31="","",N31-P31) -> 3892.1498 | R31: =IF(L31="","",O31*(1+$B$8)) -> 31302.221 | S31: =IF(L31="","",S30+P31) -> 752.51712 | T31: =IF(L31="","",Q31+T30) -> 38749.392 | AF31: =IF(AF30<($B$6*$B$7),AF30+1,"") -> 11 | AG31: =F32 -> 27469.564 | AI31: =L32 -> 11 | AJ31: =R32 -> 27397.204
A32: =IF(A31<($B$6*$B$7),A31+1,"") -> 11 | B32: =IF(A32="","",F31) -> 31367.948 | C32: =IF(A32="","",(B32*$B$8)) -> 51.806717 | D32: =IF(A32="","", $B$5) -> 3950.1909 | E32: =IF(D32="","",(D32-C32)) -> 3898.3842 | F32: =IF(A32="","", B32-E32) -> 27469.564 | G32: =IF(A32="","", (G31+C32)) -> 921.66439 | H32: =IF(A32="","",(H31+E32)) -> 42530.436 | I32: Interest from payment X1 to X2 | L32: =IF(L31<($B$6*$B$7),L31+1,"") -> 11 | M32: =IF(L32="", "", R31) -> 31302.221 | N32: =IF(L32="","",$B$5) -> 3950.1909 | O32: =IF(L32="","",M32-N32) -> 27352.03 | P32: =IF(L32="","",O31*$B$8) -> 51.61292 | Q32: =IF(L32="","",N32-P32) -> 3898.578 | R32: =IF(L32="","",O32*(1+$B$8)) -> 27397.204 | S32: =IF(L32="","",S31+P32) -> 804.13004 | T32: =IF(L32="","",Q32+T31) -> 42647.97 | AF32: =IF(AF31<($B$6*$B$7),AF31+1,"") -> 12 | AG32: =F33 -> 23564.741 | AI32: =L33 -> 12 | AJ32: =R33 -> 23485.738
A33: =IF(A32<($B$6*$B$7),A32+1,"") -> 12 | B33: =IF(A33="","",F32) -> 27469.564 | C33: =IF(A33="","",(B33*$B$8)) -> 45.368219 | D33: =IF(A33="","", $B$5) -> 3950.1909 | E33: =IF(D33="","",(D33-C33)) -> 3904.8227 | F33: =IF(A33="","", B33-E33) -> 23564.741 | G33: =IF(A33="","", (G32+C33)) -> 967.03261 | H33: =IF(A33="","",(H32+E33)) -> 46435.259 | I33: Capital from payment X1 to X2 | L33: =IF(L32<($B$6*$B$7),L32+1,"") -> 12 | M33: =IF(L33="", "", R32) -> 27397.204 | N33: =IF(L33="","",$B$5) -> 3950.1909 | O33: =IF(L33="","",M33-N33) -> 23447.013 | P33: =IF(L33="","",O32*$B$8) -> 45.174101 | Q33: =IF(L33="","",N33-P33) -> 3905.0168 | R33: =IF(L33="","",O33*(1+$B$8)) -> 23485.738 | S33: =IF(L33="","",S32+P33) -> 849.30414 | T33: =IF(L33="","",Q33+T32) -> 46552.987 | AF33: =IF(AF32<($B$6*$B$7),AF32+1,"") -> 13 | AG33: =F34 -> 19653.47 | AI33: =L34 -> 13 | AJ33: =R34 -> 19567.811
A34: =IF(A33<($B$6*$B$7),A33+1,"") -> 13 | B34: =IF(A34="","",F33) -> 23564.741 | C34: =IF(A34="","",(B34*$B$8)) -> 38.919086 | D34: =IF(A34="","", $B$5) -> 3950.1909 | E34: =IF(D34="","",(D34-C34)) -> 3911.2718 | F34: =IF(A34="","", B34-E34) -> 19653.47 | G34: =IF(A34="","", (G33+C34)) -> 1005.9517 | H34: =IF(A34="","",(H33+E34)) -> 50346.53 | I34: Last payment | L34: =IF(L33<($B$6*$B$7),L33+1,"") -> 13 | M34: =IF(L34="", "", R33) -> 23485.738 | N34: =IF(L34="","",$B$5) -> 3950.1909 | O34: =IF(L34="","",M34-N34) -> 19535.547 | P34: =IF(L34="","",O33*$B$8) -> 38.724648 | Q34: =IF(L34="","",N34-P34) -> 3911.4663 | R34: =IF(L34="","",O34*(1+$B$8)) -> 19567.811 | S34: =IF(L34="","",S33+P34) -> 888.02879 | T34: =IF(L34="","",Q34+T33) -> 50464.453 | AF34: =IF(AF33<($B$6*$B$7),AF33+1,"") -> 14 | AG34: =F35 -> 15735.738 | AI34: =L35 -> 14 | AJ34: =R35 -> 15643.414
A35: =IF(A34<($B$6*$B$7),A34+1,"") -> 14 | B35: =IF(A35="","",F34) -> 19653.47 | C35: =IF(A35="","",(B35*$B$8)) -> 32.459303 | D35: =IF(A35="","", $B$5) -> 3950.1909 | E35: =IF(D35="","",(D35-C35)) -> 3917.7316 | F35: =IF(A35="","", B35-E35) -> 15735.738 | G35: =IF(A35="","", (G34+C35)) -> 1038.411 | H35: =IF(A35="","",(H34+E35)) -> 54264.262 | L35: =IF(L34<($B$6*$B$7),L34+1,"") -> 14 | M35: =IF(L35="", "", R34) -> 19567.811 | N35: =IF(L35="","",$B$5) -> 3950.1909 | O35: =IF(L35="","",M35-N35) -> 15617.62 | P35: =IF(L35="","",O34*$B$8) -> 32.264544 | Q35: =IF(L35="","",N35-P35) -> 3917.9264 | R35: =IF(L35="","",O35*(1+$B$8)) -> 15643.414 | S35: =IF(L35="","",S34+P35) -> 920.29333 | T35: =IF(L35="","",Q35+T34) -> 54382.38 | AF35: =IF(AF34<($B$6*$B$7),AF34+1,"") -> 15 | AG35: =F36 -> 11811.536 | AI35: =L36 -> 15 | AJ35: =R36 -> 11712.535
A36: =IF(A35<($B$6*$B$7),A35+1,"") -> 15 | B36: =IF(A36="","",F35) -> 15735.738 | C36: =IF(A36="","",(B36*$B$8)) -> 25.988851 | D36: =IF(A36="","", $B$5) -> 3950.1909 | E36: =IF(D36="","",(D36-C36)) -> 3924.2021 | F36: =IF(A36="","", B36-E36) -> 11811.536 | G36: =IF(A36="","", (G35+C36)) -> 1064.3998 | H36: =IF(A36="","",(H35+E36)) -> 58188.464 | L36: =IF(L35<($B$6*$B$7),L35+1,"") -> 15 | M36: =IF(L36="", "", R35) -> 15643.414 | N36: =IF(L36="","",$B$5) -> 3950.1909 | O36: =IF(L36="","",M36-N36) -> 11693.223 | P36: =IF(L36="","",O35*$B$8) -> 25.79377 | Q36: =IF(L36="","",N36-P36) -> 3924.3972 | R36: =IF(L36="","",O36*(1+$B$8)) -> 11712.535 | S36: =IF(L36="","",S35+P36) -> 946.0871 | T36: =IF(L36="","",Q36+T35) -> 58306.777 | AF36: =IF(AF35<($B$6*$B$7),AF35+1,"") -> 16 | AG36: =F37 -> 7880.8527 | AI36: =L37 -> 16 | AJ36: =R37 -> 7775.1647
A37: =IF(A36<($B$6*$B$7),A36+1,"") -> 16 | B37: =IF(A37="","",F36) -> 11811.536 | C37: =IF(A37="","",(B37*$B$8)) -> 19.507712 | D37: =IF(A37="","", $B$5) -> 3950.1909 | E37: =IF(D37="","",(D37-C37)) -> 3930.6832 | F37: =IF(A37="","", B37-E37) -> 7880.8527 | G37: =IF(A37="","", (G36+C37)) -> 1083.9076 | H37: =IF(A37="","",(H36+E37)) -> 62119.147 | L37: =IF(L36<($B$6*$B$7),L36+1,"") -> 16 | M37: =IF(L37="", "", R36) -> 11712.535 | N37: =IF(L37="","",$B$5) -> 3950.1909 | O37: =IF(L37="","",M37-N37) -> 7762.3445 | P37: =IF(L37="","",O36*$B$8) -> 19.312309 | Q37: =IF(L37="","",N37-P37) -> 3930.8786 | R37: =IF(L37="","",O37*(1+$B$8)) -> 7775.1647 | S37: =IF(L37="","",S36+P37) -> 965.39941 | T37: =IF(L37="","",Q37+T36) -> 62237.655 | AF37: =IF(AF36<($B$6*$B$7),AF36+1,"") -> 17 | AG37: =F38 -> 3943.6776 | AI37: =L38 -> 17 | AJ37: =R38 -> 3831.291
A38: =IF(A37<($B$6*$B$7),A37+1,"") -> 17 | B38: =IF(A38="","",F37) -> 7880.8527 | C38: =IF(A38="","",(B38*$B$8)) -> 13.015869 | D38: =IF(A38="","", $B$5) -> 3950.1909 | E38: =IF(D38="","",(D38-C38)) -> 3937.1751 | F38: =IF(A38="","", B38-E38) -> 3943.6776 | G38: =IF(A38="","", (G37+C38)) -> 1096.9234 | H38: =IF(A38="","",(H37+E38)) -> 66056.322 | L38: =IF(L37<($B$6*$B$7),L37+1,"") -> 17 | M38: =IF(L38="", "", R37) -> 7775.1647 | N38: =IF(L38="","",$B$5) -> 3950.1909 | O38: =IF(L38="","",M38-N38) -> 3824.9738 | P38: =IF(L38="","",O37*$B$8) -> 12.820143 | Q38: =IF(L38="","",N38-P38) -> 3937.3708 | R38: =IF(L38="","",O38*(1+$B$8)) -> 3831.291 | S38: =IF(L38="","",S37+P38) -> 978.21955 | T38: =IF(L38="","",Q38+T37) -> 66175.026 | AF38: =IF(AF37<($B$6*$B$7),AF37+1,"") -> 18 | AG38: =F39 -> -8.1581675e-10 | AI38: =L39 -> 18 | AJ38: =R39 -> -119.0963
A39: =IF(A38<($B$6*$B$7),A38+1,"") -> 18 | B39: =IF(A39="","",F38) -> 3943.6776 | C39: =IF(A39="","",(B39*$B$8)) -> 6.5133042 | D39: =IF(A39="","", $B$5) -> 3950.1909 | E39: =IF(D39="","",(D39-C39)) -> 3943.6776 | F39: =IF(A39="","", B39-E39) -> -8.1581675e-10 | G39: =IF(A39="","", (G38+C39)) -> 1103.4367 | H39: =IF(A39="","",(H38+E39)) -> 70000 | L39: =IF(L38<($B$6*$B$7),L38+1,"") -> 18 | M39: =IF(L39="", "", R38) -> 3831.291 | N39: =IF(L39="","",$B$5) -> 3950.1909 | O39: =IF(L39="","",M39-N39) -> -118.89992 | P39: =IF(L39="","",O38*$B$8) -> 6.3172551 | Q39: =IF(L39="","",N39-P39) -> 3943.8737 | R39: =IF(L39="","",O39*(1+$B$8)) -> -119.0963 | S39: =IF(L39="","",S38+P39) -> 984.53681 | T39: =IF(L39="","",Q39+T38) -> 70118.9 | AF39: =IF(AF38<($B$6*$B$7),AF38+1,"") -> 19 | AG39: =F40 -> -3950.1909 | AI39: =L40 -> 19 | AJ39: =R40 -> -4076.008
A40: =IF(A39<($B$6*$B$7),A39+1,"") -> 19 | B40: =IF(A40="","",F39) -> -8.1581675e-10 | C40: =IF(A40="","",(B40*$B$8)) -> -1.3473877e-12 | D40: =IF(A40="","", $B$5) -> 3950.1909 | E40: =IF(D40="","",(D40-C40)) -> 3950.1909 | F40: =IF(A40="","", B40-E40) -> -3950.1909 | G40: =IF(A40="","", (G39+C40)) -> 1103.4367 | H40: =IF(A40="","",(H39+E40)) -> 73950.191 | L40: =IF(L39<($B$6*$B$7),L39+1,"") -> 19 | M40: =IF(L40="", "", R39) -> -119.0963 | N40: =IF(L40="","",$B$5) -> 3950.1909 | O40: =IF(L40="","",M40-N40) -> -4069.2872 | P40: =IF(L40="","",O39*$B$8) -> -0.19637289 | Q40: =IF(L40="","",N40-P40) -> 3950.3873 | R40: =IF(L40="","",O40*(1+$B$8)) -> -4076.008 | S40: =IF(L40="","",S39+P40) -> 984.34044 | T40: =IF(L40="","",Q40+T39) -> 74069.287 | AF40: =IF(AF39<($B$6*$B$7),AF39+1,"") | AG40: =F41 | AI40: =L41 | AJ40: =R41
A41: =IF(A40<($B$6*$B$7),A40+1,"") | B41: =IF(A41="","",F40) | C41: =IF(A41="","",(B41*$B$8)) | D41: =IF(A41="","", $B$5) | E41: =IF(D41="","",(D41-C41)) | F41: =IF(A41="","", B41-E41) | G41: =IF(A41="","", (G40+C41)) | H41: =IF(A41="","",(H40+E41)) | L41: =IF(L40<($B$6*$B$7),L40+1,"") | M41: =IF(L41="", "", R40) | N41: =IF(L41="","",$B$5) | O41: =IF(L41="","",M41-N41) | P41: =IF(L41="","",O40*$B$8) | Q41: =IF(L41="","",N41-P41) | R41: =IF(L41="","",O41*(1+$B$8)) | S41: =IF(L41="","",S40+P41) | T41: =IF(L41="","",Q41+T40) | AF41: =IF(AF40<($B$6*$B$7),AF40+1,"") | AG41: =F42 | AI41: =L42 | AJ41: =R42
A42: =IF(A41<($B$6*$B$7),A41+1,"") | B42: =IF(A42="","",F41) | C42: =IF(A42="","",(B42*$B$8)) | D42: =IF(A42="","", $B$5) | E42: =IF(D42="","",(D42-C42)) | F42: =IF(A42="","", B42-E42) | G42: =IF(A42="","", (G41+C42)) | H42: =IF(A42="","",(H41+E42)) | L42: =IF(L41<($B$6*$B$7),L41+1,"") | M42: =IF(L42="", "", R41) | N42: =IF(L42="","",$B$5) | O42: =IF(L42="","",M42-N42) | P42: =IF(L42="","",O41*$B$8) | Q42: =IF(L42="","",N42-P42) | R42: =IF(L42="","",O42*(1+$B$8)) | S42: =IF(L42="","",S41+P42) | T42: =IF(L42="","",Q42+T41) | AF42: =IF(AF41<($B$6*$B$7),AF41+1,"") | AG42: =F43 | AI42: =L43 | AJ42: =R43
...

Sheet Investment(Single + Annuity)
A1: INVESTMENTS(Single + Annuity)
A3: Givens | E3: Unkowns | S3: Initial Single Investment | T3: Arrears
A4: Initial Single inestment | E4: Loan Type: | F4: Arrears | H4: Investment component(Variable): | I4: Present Value | S4: Payment | T4: Advance
A5: Annuity Cashflow | S5: Period per year
S6: Number of years
S7: Present Value
A8: Effective Periodic interest rate | H8: VALUE | I8: =IF(AND(F4=T3,I4=S3),'Investments back office'!I10,IF(AND(F4=T3,I4=S4),'Investments back office'!I11,IF(AND(F4=T3,I4=S5),'Investments back office'!I12,IF(AND(F4=T3,I4=S6),'Investments back office'!I13,IF(AND(F4=T3,I4=S7),'Investments back office'!I16,IF(AND(F4=T3,I4=S8),'Investments back office'!I17,IF(AND(F4=T3,I4=S9),'Investments back office'!I18,IF(AND(F4=T3,I4=S10),'Investments back office'!I19,IF(AND(F4=T4,I4=S3),'Investments back office'!J10,IF(AND(F4=T4,I4=S4),'Investments back office'!J11,IF(AND(F4=T4,I4=S5),'Investments back office'!J12,IF(AND(F4=T4,I4=S6),'Investments back office'!J13,IF(AND(F4=T4,I4=S7),'Investments back office'!J16,IF(AND(F4=T4,I4=S8),'Investments back office'!J17,IF(AND(F4=T4,I4=S9),'Investments back office'!J18,IF(AND(F4=T4,I4=S10),'Investments back office'!J19)))))))))))))))) -> 0 | S8: Total Interest
A9: Specific time (Year) | S9: Future Value
A10: Specific time (Periods) | S10: Total Periods
A11: Number of Payment (K) | H11: REAL FUTURE VALUE | I11: =IF(I4=I18,I8*(1+5%)^(-B9)," ")
A12: Start period (Interest)
A13: End period(Interest)
A14: Future Value | E14: To Convert Interest Rates:
E16: Home
I18: Future Value

Sheet Investments back office
A1: Givens
A2: Initial Single inestment | B2: ='Investment(Single + Annuity)'!B4 -> 0
A3: Annuity Cashflow | B3: ='Investment(Single + Annuity)'!B5 -> 0
A4: Years | B4: ='Investment(Single + Annuity)'!B6 -> 0
A6: Effective Periodic or nominal interest rate | B6: ='Investment(Single + Annuity)'!B8 -> 0
A7: Specific time (Year) | B7: ='Investment(Single + Annuity)'!B9 -> 0
A8: Pecific year in periods | B8: ='Investment(Single + Annuity)'!B10 -> 0
A9: Number of Payment (K) | B9: ='Assignment4 (User Interface)'!B11 -> 1 | I9: Arrears | J9: Advance
A10: Start Period (Interest) | B10: ='Assignment4 (User Interface)'!B12 -> 1 | H10: Initial Single Investment | I10: =(B12-(B3*(((1+B6)^(B7*B8)-1)/B6)))/((1+B6)^(B7*B8)) -> #DIV/0! | J10: =(B12-(B3*(1+B6)*(((1+B6)^(B7*B8)-1)/B6)))/((1+B6)^(B7*B8)) -> #DIV/0!
A11: End Period (Interest) | B11: ='Assignment4 (User Interface)'!B13 -> 2 | H11: Payment | I11: =((B12 - (B2*(1+B6)^(B7*B8)))*B6)/(((1+B6)^(B7*B8))-1) -> #DIV/0! | J11: =((B12 - (B2*(1+B6)^(B7*B8)))*B6)/((1+B6)*(((1+B6)^(B7*B8))-1)) -> #DIV/0!
A12: Future Value | B12: 1002573.1 | H12: Period to of investment | I12: =((LN((B12*B6+B3)/(B2*B6+B3)))/(LN(1+B6)))*(1/B7) -> #DIV/0! | J12: =((LN((B12 +( B3*(1+B6))/B6)/(B2 + (B3*(1+B6))/B6)))/(LN(1+B6)))*(1/B7) -> #DIV/0!
H13: Number of years | I13: =((LN((B12*B6+B3)/(B2*B6+B3)))/(LN(1+B6)))*(1/B8) -> #DIV/0! | J13: =((LN((B12 +( B3*(1+B6))/B6)/(B2 + (B3*(1+B6))/B6)))/(LN(1+B6)))*(1/B8) -> #DIV/0!
H16: Present Value | I16: =I18*(1+B6)^(-B7*B8) -> 0 | J16: =J18*(1+B6)^(-B7*B8) -> 0
H17: Total Interest | I17: {=LOOKUP(2, 1/(G22:G607<>""), G22:G607)} -> 0 | J17: {=LOOKUP(2, 1/(P22:P607<>""), P22:P607)} -> 0
H18: Future Value | I18: {=LOOKUP(2, 1/(F22:F607<>""), F22:F607)} -> 0 | J18: {=LOOKUP(2, 1/(O22:O607<>""), O22:O607)} -> 0
H19: Total Periods | I19: =((LN((B12*B6+B3)/(B2*B6+B3)))/(LN(1+B6))) -> #DIV/0! | J19: =((LN((B12 +( B3*(1+B6))/B6)/(B2 + (B3*(1+B6))/B6)))/(LN(1+B6))) -> #DIV/0!
A20: Amortization table (Arrears) | J20: Amortization table (Advance)
A21: Period | B21: Balance at Start | C21: Interest | D21: Payment | E21: Capital | F21: Balance at end | G21: Interest so far | J21: Period | K21: Balance at Start | L21: Interest | M21: Payment | N21: Capital | O21: Balance at end | P21: Interest so far
